FAIL tests/providers-stdlib/childProcess/__error_while_running.ts


  ● Test suite failed to run

    Test context "childProcess" failed while running setdown logic inside Jest "afterAll": 
    The child process exited with non-zero exit code: 1. Its combined stderr and stdout output was:

    ----------------------------------------------------------------
    ready
    /Users/jasonkuhrt/projects/prisma-labs/konn/tests/providers-stdlib/childProcess/__error_while_running.fixture.ts:4
        throw new Error('Something went wrong while running.');
              ^
    Error: Something went wrong while running.

      2 |
      3 | setTimeout(() => {
    > 4 |   throw new Error('Something went wrong while running.')
        |           ^
      5 | }, 100)
      6 |
      7 | process.on('SIGTERM', () => {

      at Timeout._onTimeout (tests/providers-stdlib/childProcess/__error_while_running.fixture.ts:4:11)
      ---------------------------------------------------------------- 
      Command failed with exit code 1: ts-node ./tests/providers-stdlib/childProcess/__error_while_running.fixture.ts
      /Users/jasonkuhrt/projects/prisma-labs/konn/tests/providers-stdlib/childProcess/__error_while_running.fixture.ts:4
          throw new Error('Something went wrong while running.');
                ^
      Error: Something went wrong while running.
      at Timeout._onTimeout (tests/providers-stdlib/childProcess/__error_while_running.fixture.ts:4:11)
      ready
      at src/runners.ts:66:16
      Error: The child process exited with non-zero exit code: 1. Its combined stderr and stdout output was:
      ----------------------------------------------------------------
      ready
      /Users/jasonkuhrt/projects/prisma-labs/konn/tests/providers-stdlib/childProcess/__error_while_running.fixture.ts:4
          throw new Error('Something went wrong while running.');
                ^
      Error: Something went wrong while running.
      at Timeout._onTimeout (tests/providers-stdlib/childProcess/__error_while_running.fixture.ts:4:11)
      ---------------------------------------------------------------- 
      Command failed with exit code 1: ts-node ./tests/providers-stdlib/childProcess/__error_while_running.fixture.ts
      /Users/jasonkuhrt/projects/prisma-labs/konn/tests/providers-stdlib/childProcess/__error_while_running.fixture.ts:4
          throw new Error('Something went wrong while running.');
                ^
      Error: Something went wrong while running.
      at Timeout._onTimeout (tests/providers-stdlib/childProcess/__error_while_running.fixture.ts:4:11)
      ready
      at Object.setdown (src/Providers/ChildProcess/ChildProcess.ts:230:22)
      at src/runners.ts:60:7
      Error: Command failed with exit code 1: ts-node ./tests/providers-stdlib/childProcess/__error_while_running.fixture.ts
      /Users/jasonkuhrt/projects/prisma-labs/konn/tests/providers-stdlib/childProcess/__error_while_running.fixture.ts:4
          throw new Error('Something went wrong while running.');
                ^
      Error: Something went wrong while running.
      at Timeout._onTimeout (tests/providers-stdlib/childProcess/__error_while_running.fixture.ts:4:11)
      ready
      at makeError (node_modules/execa/lib/error.js:60:11)
      at handlePromise (node_modules/execa/index.js:118:26)

Test Suites: 1 failed, 1 total
Tests:       1 passed, 1 total
Snapshots:   0 total
Time:        3.434 s, estimated 4 s
Ran all test suites.